Workbook

Sheet Tracker
A1: NDMA — AI-Integrated Digital Twin Command Dashboard · Project Tracker
A2: Source: NDMA_Digital_Twin_Proposal.pdf · Phase 1 = one pilot district, riverine flood · Phase 2 = landslide, cyclone, more sensor/crowd inputs · Phase 3 = multi-district scale-up · Edit Start, End and Status; Working days recalculates (weekends and the Holidays tab excluded). Dates are planned from dependencies starting 12 Oct 26.
A3: Module | B3: Category | C3: Task | D3: Sub Task | E3: Description | F3: Acceptance criteria / Definition of done | G3: Start | H3: End | I3: Working days | J3: Status | K3: Dependency / Blocker | L3: Comments | M3: Artifacts
A4: A – Programme Setup & Governance | B4: 1. Project Initiation | C4: Solution Proposal | D4: Draft AI-integrated Digital Twin proposal | E4: Write the solution proposal: problem statement, five-layer solution, dashboard features, usage example, data sources, risks and expected impact. | F4: Done when: proposal (PDF + DOCX) is complete and committed to the repo. | G4: 46286 | H4: 46297 | I4: =NETWORKDAYS(G4,H4,Holidays!$A$2:$A$40) -> 10 | J4: Done | M4: NDMA_Digital_Twin_Proposal.pdf; NDMA_Digital_Twin_Proposal (1).docx
D5: Proposal walkthrough and sign-off with NDMA | E5: Present the proposal to NDMA, capture feedback and get written go-ahead for Phase 1. | F5: Done when: NDMA sign-off (email/minutes) received and feedback logged. | G5: 46307 | H5: 46310 | I5: =NETWORKDAYS(G5,H5,Holidays!$A$2:$A$40) -> 4 | J5: Not Started | K5: After: Draft AI-integrated Digital Twin proposal (P0). Needs: NDMA meeting slot for walkthrough.
C6: Scope & Pilot | D6: Select Phase 1 pilot district | E6: Pick one well-mapped, flood-prone district with CWC gauges, good DEM coverage and a willing DEOC (mitigates the terrain-resolution risk). | F6: Done when: pilot district agreed in writing with a scored selection matrix. | G6: 46311 | H6: 46318 | I6: =NETWORKDAYS(G6,H6,Holidays!$A$2:$A$40) -> 5 | J6: Not Started | K6: After: Proposal walkthrough and sign-off with NDMA (P1). Needs: NDMA / State SDMA nomination of candidate districts.
D7: Lock Phase 1 hazard and scope | E7: Phase 1 = riverine flood in the pilot district. Landslide, cyclone and wider sensor/crowd inputs move to Phase 2; multi-district scale-up is Phase 3. | F7: Done when: in/out-of-scope list signed off by NDMA. | G7: 46321 | H7: 46323 | I7: =NETWORKDAYS(G7,H7,Holidays!$A$2:$A$40) -> 3 | J7: Not Started | K7: After: Select Phase 1 pilot district (P2).
D8: User roles and operational workflows | E8: Interview NDMA, SEOC, DEOC and NDRF/SDRF users; map how they plan shelters, routes and deployments today. | F8: Done when: personas, current-vs-future workflow maps and a prioritised needs list are documented. | G8: 46311 | H8: 46321 | I8: =NETWORKDAYS(G8,H8,Holidays!$A$2:$A$40) -> 6 | J8: Not Started | K8: After: Proposal walkthrough and sign-off with NDMA (P1).
D9: Success metrics and acceptance bar | E9: Agree measurable targets: flood-extent accuracy (IoU/CSI), forecast lead time, route recompute time, dashboard load time. | F9: Done when: metric targets are agreed with NDMA and referenced by validation tasks. | G9: 46324 | H9: 46329 | I9: =NETWORKDAYS(G9,H9,Holidays!$A$2:$A$40) -> 4 | J9: Not Started | K9: After: Lock Phase 1 hazard and scope (P3); User roles and operational workflows (P4).
B10: 2. Data Agreements & Governance | C10: Data-Sharing Agreements | D10: IMD data-sharing agreement | E10: Formal agreement for rainfall nowcasts, district forecasts and cyclone bulletins (API/FTP access). | F10: Done when: signed agreement and working credentials/endpoint for the pilot district. | G10: 46321 | H10: 46346 | I10: =NETWORKDAYS(G10,H10,Holidays!$A$2:$A$40) -> 20 | J10: Not Started | K10: After: Select Phase 1 pilot district (P2). Needs: IMD nodal officer; NDMA letter of request.
D11: CWC data-sharing agreement | E11: Agreement for real-time river gauge levels and flood forecasts. | F11: Done when: signed agreement and live gauge feed access for pilot basins. | G11: 46321 | H11: 46346 | I11: =NETWORKDAYS(G11,H11,Holidays!$A$2:$A$40) -> 20 | J11: Not Started | K11: After: Select Phase 1 pilot district (P2). Needs: CWC nodal officer; NDMA letter of request.
D12: ISRO / NRSC satellite data access | E12: Access to optical and SAR imagery and flood maps (Bhuvan / NDEM) for the pilot district. | F12: Done when: imagery access confirmed and a sample scene downloaded. | G12: 46321 | H12: 46353 | I12: =NETWORKDAYS(G12,H12,Holidays!$A$2:$A$40) -> 25 | J12: Not Started | K12: After: Select Phase 1 pilot district (P2). Needs: NRSC approval via NDMA.
D13: Survey of India high-resolution DEM licence | E13: Licence for high-resolution elevation data — the base terrain of the 3D twin. | F13: Done when: licence signed and DEM tiles for the pilot district received. | G13: 46321 | H13: 46346 | I13: =NETWORKDAYS(G13,H13,Holidays!$A$2:$A$40) -> 20 | J13: Not Started | K13: After: Select Phase 1 pilot district (P2). Needs: SoI licence approval.
D14: Census / LGD data access | E14: Population, household and administrative boundary data for impact and shelter sizing. | F14: Done when: ward/village-level population and LGD boundaries for the pilot district are available. | G14: 46321 | H14: 46332 | I14: =NETWORKDAYS(G14,H14,Holidays!$A$2:$A$40) -> 10 | J14: Not Started | K14: After: Select Phase 1 pilot district (P2).
D15: Google Maps Platform licence and billing | E15: Enable Roads, Places and Traffic APIs with a government billing account and usage caps. | F15: Done when: API keys issued with quotas and a cost estimate approved. | G15: 46311 | H15: 46323 | I15: =NETWORKDAYS(G15,H15,Holidays!$A$2:$A$40) -> 8 | J15: Not Started | K15: After: Proposal walkthrough and sign-off with NDMA (P1). Needs: budget approval for API usage.
D16: Commercial high-resolution imagery procurement | E16: Procure fine-resolution imagery for the pilot district to sharpen terrain and infrastructure detail. | F16: Done when: purchase order issued and imagery delivered. | G16: 46321 | H16: 46360 | I16: =NETWORKDAYS(G16,H16,Holidays!$A$2:$A$40) -> 30 | J16: Not Started | K16: After: Select Phase 1 pilot district (P2). Needs: procurement approval (GeM). | L16: Pilot district only in Phase 1.
C17: Privacy & Data Governance | D17: Data governance and privacy policy | E17: Policy covering citizen location/photo data and social media signals under the DPDP Act 2023: purpose limitation, minimisation, retention, access. | F17: Done when: policy approved by NDMA legal and published internally. | G17: 46311 | H17: 46332 | I17: =NETWORKDAYS(G17,H17,Holidays!$A$2:$A$40) -> 15 | J17: Not Started | K17: After: Proposal walkthrough and sign-off with NDMA (P1). Needs: NDMA legal review. | L17: Runs alongside the technical build (proposal risk: data privacy & consent).
D18: Data classification and retention rules | E18: Classify each data source (public / restricted / personal) and set retention periods. | F18: Done when: every ingested source has a class and retention rule applied in the pipeline config. | G18: 46335 | H18: 46339 | I18: =NETWORKDAYS(G18,H18,Holidays!$A$2:$A$40) -> 5 | J18: Not Started | K18: After: Data governance and privacy policy (G1).
D19: Consent flow for citizen ground reports | E19: Consent text and opt-in flow for WhatsApp / SACHET reports (photo + location). | F19: Done when: consent text approved and recorded with every citizen report. | G19: 46335 | H19: 46339 | I19: =NETWORKDAYS(G19,H19,Holidays!$A$2:$A$40) -> 5 | J19: Not Started | K19: After: Data governance and privacy policy (G1).
A20: B – Unified Data Ingestion (Layer 1) | B20: 3. Ingestion Foundation | C20: Common Data Model | D20: Canonical schema for all feeds | E20: One schema for every source: timestamp (UTC + IST), geometry, source, unit, confidence and raw-payload reference. | F20: Done when: schema documented and validated against samples from every Phase 1 source. | G20: 46324 | H20: 46335 | I20: =NETWORKDAYS(G20,H20,Holidays!$A$2:$A$40) -> 8 | J20: Not Started | K20: After: Lock Phase 1 hazard and scope (P3).
C21: Ingestion Framework | D21: Connector framework and scheduler | E21: Reusable connector framework with scheduling, retries, back-fill and idempotent loads so feeds stay fresh without manual effort. | F21: Done when: scheduled runs complete, resume after interruption and never run twice at once. | G21: 46336 | H21: 46349 | I21: =NETWORKDAYS(G21,H21,Holidays!$A$2:$A$40) -> 10 | J21: Not Started | K21: After: Canonical schema for all feeds (I1); Dev / test / prod environments as code (H1).
D22: Spatial data store (PostGIS + object storage) | E22: Store vector layers, time-series and rasters/imagery in one spatially indexed store. | F22: Done when: store is provisioned in dev/test with spatial indexes and backup. | G22: 46336 | H22: 46345 | I22: =NETWORKDAYS(G22,H22,Holidays!$A$2:$A$40) -> 8 | J22: Not Started | K22: After: Canonical schema for all feeds (I1); Dev / test / prod environments as code (H1).
D23: Pipeline status view (last run, errors, owner) | E23: Simple view showing, per source, when it last succeeded, what failed and who owns it. | F23: Done when: operations can spot a stale/failed feed without engineering help. | G23: 46350 | H23: 46356 | I23: =NETWORKDAYS(G23,H23,Holidays!$A$2:$A$40) -> 5 | J23: Not Started | K23: After: Connector framework and scheduler (I2).
B24: 4. Agency Feeds | C24: IMD | D24: IMD connector (rainfall, forecasts, cyclone bulletins) | E24: Pull nowcasts, district rainfall forecasts and bulletins into the canonical schema. | F24: Done when: IMD data for the pilot district lands every cycle with < 1 cycle lag. | G24: 46350 | H24: 46359 | I24: =NETWORKDAYS(G24,H24,Holidays!$A$2:$A$40) -> 8 | J24: Not Started | K24: After: Connector framework and scheduler (I2); IMD data-sharing agreement (D1).
C25: CWC | D25: CWC connector (gauge levels, flood forecasts) | E25: Pull river gauge levels, danger/warning marks and flood forecasts for the pilot basins. | F25: Done when: all pilot-basin gauges update on schedule with danger marks attached. | G25: 46350 | H25: 46359 | I25: =NETWORKDAYS(G25,H25,Holidays!$A$2:$A$40) -> 8 | J25: Not Started | K25: After: Connector framework and scheduler (I2); CWC data-sharing agreement (D2).
C26: ISRO / NRSC | D26: Satellite imagery connector (optical + SAR) | E26: Ingest optical and SAR scenes and NRSC flood-extent products for change detection. | F26: Done when: new scenes for the pilot district are catalogued automatically. | G26: 46356 | H26: 46367 | I26: =NETWORKDAYS(G26,H26,Holidays!$A$2:$A$40) -> 10 | J26: Not Started | K26: After: Connector framework and scheduler (I2); ISRO / NRSC satellite data access (D3).
C27: Open Satellite | D27: Copernicus Sentinel-1/2 and Landsat connector | E27: Open imagery for flood-extent and land-cover validation (no agreement needed). | F27: Done when: scenes over the pilot district are searchable by date and cloud cover. | G27: 46350 | H27: 46359 | I27: =NETWORKDAYS(G27,H27,Holidays!$A$2:$A$40) -> 8 | J27: Not Started | K27: After: Connector framework and scheduler (I2).
B28: 5. Static & Reference Layers | C28: Terrain | D28: Ingest and tile SoI DEM | E28: Clean, reproject and tile the DEM; fill voids from open DEMs where needed. | F28: Done when: seamless DEM for the pilot district is served as tiles with void report. | G28: 46349 | H28: 46356 | I28: =NETWORKDAYS(G28,H28,Holidays!$A$2:$A$40) -> 6 | J28: Not Started | K28: After: Spatial data store (PostGIS + object storage) (I3); Survey of India high-resolution DEM licence (D4).
C29: Population & Boundaries | D29: Census / LGD population and boundaries | E29: Load ward/village boundaries and population, households and age bands. | F29: Done when: every zone in the pilot district has population and household counts. | G29: 46346 | H29: 46353 | I29: =NETWORKDAYS(G29,H29,Holidays!$A$2:$A$40) -> 6 | J29: Not Started | K29: After: Spatial data store (PostGIS + object storage) (I3); Census / LGD data access (D5).
C30: Infrastructure | D30: Roads, bridges and critical facilities layer | E30: Build roads, bridges, hospitals, schools and govt buildings from OSM + Google Places/Roads. | F30: Done when: routable road network and facility layer cover the pilot district. | G30: 46346 | H30: 46357 | I30: =NETWORKDAYS(G30,H30,Holidays!$A$2:$A$40) -> 8 | J30: Not Started | K30: After: Spatial data store (PostGIS + object storage) (I3); Google Maps Platform licence and billing (D6).
C31: History | D31: Historical disaster records | E31: Collect past flood events: dates, gauge peaks, mapped extents, damage and relief records. | F31: Done when: at least 5 past flood events are catalogued with extents for backtesting. | G31: 46346 | H31: 46359 | I31: =NETWORKDAYS(G31,H31,Holidays!$A$2:$A$40) -> 10 | J31: Not Started | K31: After: Spatial data store (PostGIS + object storage) (I3). | L31: Used to calibrate and backtest every model.
C32: Resources | D32: IDRN resource inventory import | E32: Import India Disaster Resource Network equipment and team inventory for the pilot state. | F32: Done when: IDRN inventory is queryable by location and resource type. | G32: 46346 | H32: 46352 | I32: =NETWORKDAYS(G32,H32,Holidays!$A$2:$A$40) -> 5 | J32: Not Started | K32: After: Spatial data store (PostGIS + object storage) (I3). Needs: IDRN data access via NDMA.
B33: 6. Sensor & Crowdsourced Feeds | C33: Hardware Sensors | D33: River / rain gauge sensor telemetry (pilot) | E33: Ingest telemetry from pilot river-level and rainfall gauges (MQTT/HTTP). | F33: Done when: pilot sensors stream into the store with device health status. | G33: 46350 | H33: 46363 | I33: =NETWORKDAYS(G33,H33,Holidays!$A$2:$A$40) -> 10 | J33: Not Started | K33: After: Connector framework and scheduler (I2). Needs: sensor vendor / state agency feed access.
C34: Ground Reporting | D34: WhatsApp ground-reporting bot | E34: Structured bot for field staff and citizens to send photo + location + short description. | F34: Done when: reports arrive geotagged with consent recorded and reach the ingestion layer. | G34: 46350 | H34: 46365 | I34: =NETWORKDAYS(G34,H34,Holidays!$A$2:$A$40) -> 12 | J34: Not Started | K34: After: Connector framework and scheduler (I2); Consent flow for citizen ground reports (G3). Needs: WhatsApp Business API account.
D35: Report verification and trust score | E35: De-duplicate, geo-check and score reports (image checks, reporter history, agreement with sensors) before they are trusted. | F35: Done when: every report carries a trust score and low-trust reports are held for review. | G35: 46366 | H35: 46379 | I35: =NETWORKDAYS(G35,H35,Holidays!$A$2:$A$40) -> 10 | J35: Not Started | K35: After: WhatsApp ground-reporting bot (I17). | L35: Mitigation for crowdsourced misinformation risk.
B36: 7. Data Quality | C36: Normalisation | D36: Units, CRS and time-zone normalisation | E36: Convert all feeds to common units, one CRS and UTC/IST timestamps. | F36: Done when: no unit/CRS mismatches across Phase 1 sources in the QA report. | G36: 46360 | H36: 46366 | I36: =NETWORKDAYS(G36,H36,Holidays!$A$2:$A$40) -> 5 | J36: Not Started | K36: After: IMD connector (rainfall, forecasts, cyclone bulletins) (I5); CWC connector (gauge levels, flood forecasts) (I6).
C37: Quality Rules | D37: Staleness, gap and outlier rules with alerts | E37: Rules that flag stale feeds, missing values and impossible readings; alert the data owner. | F37: Done when: rules are documented, applied and alerts fire in test. | G37: 46367 | H37: 46374 | I37: =NETWORKDAYS(G37,H37,Holidays!$A$2:$A$40) -> 6 | J37: Not Started | K37: After: Units, CRS and time-zone normalisation (I21).
A38: C – AI/ML Prediction Engine (Layer 2) | B38: 8. EDA & Feature Prep | C38: EDA | D38: EDA on historical floods, rainfall and gauges | E38: Study rainfall–gauge lag, upstream/downstream relationships and past extents in the pilot basin. | F38: Done when: findings and modelling decisions are documented in a notebook. | G38: 46360 | H38: 46371 | I38: =NETWORKDAYS(G38,H38,Holidays!$A$2:$A$40) -> 8 | J38: Not Started | K38: After: Historical disaster records (I12); CWC connector (gauge levels, flood forecasts) (I6); IMD connector (rainfall, forecasts, cyclone bulletins) (I5).
C39: Features | D39: Feature store (rainfall accumulations, upstream levels, soil, land cover) | E39: Reusable, versioned features for all flood models. | F39: Done when: features are reproducible from raw data with one command. | G39: 46377 | H39: 46387 | I39: =NETWORKDAYS(G39,H39,Holidays!$A$2:$A$40) -> 8 | J39: Not Started | K39: After: EDA on historical floods, rainfall and gauges (M1); Staleness, gap and outlier rules with alerts (I22).
B40: 9. Flood Forecasting | C40: Hydraulic Model | D40: Hydraulic/hydrological model set-up on DEM | E40: Set up a physics model (e.g. HEC-RAS 2D / LISFLOOD-FP) for the pilot basin and calibrate on past events. | F40: Done when: model reproduces at least 3 historical extents within the agreed accuracy bar. | G40: 46372 | H40: 46393 | I40: =NETWORKDAYS(G40,H40,Holidays!$A$2:$A$40) -> 15 | J40: Not Started | K40: After: Ingest and tile SoI DEM (I9); EDA on historical floods, rainfall and gauges (M1).
...

Sheet Summary
A1: Summary by Module
A2: All figures are formulas over the Tracker tab; they update as Status and dates change.
A3: Module | B3: Sub tasks | C3: Done | D3: In Progress | E3: Not Started | F3: Blocked | G3: % Done | H3: Start | I3: End | J3: Working days
A4: A – Programme Setup & Governance | B4: =COUNTA(Tracker!$D$4:$D$19) -> 16 | C4: =COUNTIF(Tracker!$J$4:$J$19,"Done") -> 1 | D4: =COUNTIF(Tracker!$J$4:$J$19,"In Progress") -> 0 | E4: =COUNTIF(Tracker!$J$4:$J$19,"Not Started") -> 15 | F4: =COUNTIF(Tracker!$J$4:$J$19,"Blocked") -> 0 | G4: =IF(B4=0,0,C4/B4) -> 0.0625 | H4: =MIN(Tracker!$G$4:$G$19) -> 46286 | I4: =MAX(Tracker!$H$4:$H$19) -> 46360 | J4: =NETWORKDAYS(H4,I4,Holidays!$A$2:$A$40) -> 54
A5: B – Unified Data Ingestion (Layer 1) | B5: =COUNTA(Tracker!$D$20:$D$37) -> 18 | C5: =COUNTIF(Tracker!$J$20:$J$37,"Done") -> 0 | D5: =COUNTIF(Tracker!$J$20:$J$37,"In Progress") -> 0 | E5: =COUNTIF(Tracker!$J$20:$J$37,"Not Started") -> 18 | F5: =COUNTIF(Tracker!$J$20:$J$37,"Blocked") -> 0 | G5: =IF(B5=0,0,C5/B5) -> 0 | H5: =MIN(Tracker!$G$20:$G$37) -> 46324 | I5: =MAX(Tracker!$H$20:$H$37) -> 46379 | J5: =NETWORKDAYS(H5,I5,Holidays!$A$2:$A$40) -> 40
A6: C – AI/ML Prediction Engine (Layer 2) | B6: =COUNTA(Tracker!$D$38:$D$49) -> 12 | C6: =COUNTIF(Tracker!$J$38:$J$49,"Done") -> 0 | D6: =COUNTIF(Tracker!$J$38:$J$49,"In Progress") -> 0 | E6: =COUNTIF(Tracker!$J$38:$J$49,"Not Started") -> 12 | F6: =COUNTIF(Tracker!$J$38:$J$49,"Blocked") -> 0 | G6: =IF(B6=0,0,C6/B6) -> 0 | H6: =MIN(Tracker!$G$38:$G$49) -> 46360 | I6: =MAX(Tracker!$H$38:$H$49) -> 46485 | J6: =NETWORKDAYS(H6,I6,Holidays!$A$2:$A$40) -> 87
A7: D – Digital Twin Simulation (Layer 3) | B7: =COUNTA(Tracker!$D$50:$D$59) -> 10 | C7: =COUNTIF(Tracker!$J$50:$J$59,"Done") -> 0 | D7: =COUNTIF(Tracker!$J$50:$J$59,"In Progress") -> 0 | E7: =COUNTIF(Tracker!$J$50:$J$59,"Not Started") -> 10 | F7: =COUNTIF(Tracker!$J$50:$J$59,"Blocked") -> 0 | G7: =IF(B7=0,0,C7/B7) -> 0 | H7: =MIN(Tracker!$G$50:$G$59) -> 46324 | I7: =MAX(Tracker!$H$50:$H$59) -> 46507 | J7: =NETWORKDAYS(H7,I7,Holidays!$A$2:$A$40) -> 129
A8: E – Planning & Decision Support (Layer 4) | B8: =COUNTA(Tracker!$D$60:$D$73) -> 14 | C8: =COUNTIF(Tracker!$J$60:$J$73,"Done") -> 0 | D8: =COUNTIF(Tracker!$J$60:$J$73,"In Progress") -> 0 | E8: =COUNTIF(Tracker!$J$60:$J$73,"Not Started") -> 14 | F8: =COUNTIF(Tracker!$J$60:$J$73,"Blocked") -> 0 | G8: =IF(B8=0,0,C8/B8) -> 0 | H8: =MIN(Tracker!$G$60:$G$73) -> 46457 | I8: =MAX(Tracker!$H$60:$H$73) -> 46517 | J8: =NETWORKDAYS(H8,I8,Holidays!$A$2:$A$40) -> 42
A9: F – Force Coordination & Control (Layer 5) | B9: =COUNTA(Tracker!$D$74:$D$81) -> 8 | C9: =COUNTIF(Tracker!$J$74:$J$81,"Done") -> 0 | D9: =COUNTIF(Tracker!$J$74:$J$81,"In Progress") -> 0 | E9: =COUNTIF(Tracker!$J$74:$J$81,"Not Started") -> 8 | F9: =COUNTIF(Tracker!$J$74:$J$81,"Blocked") -> 0 | G9: =IF(B9=0,0,C9/B9) -> 0 | H9: =MIN(Tracker!$G$74:$G$81) -> 46353 | I9: =MAX(Tracker!$H$74:$H$81) -> 46526 | J9: =NETWORKDAYS(H9,I9,Holidays!$A$2:$A$40) -> 121
A10: G – Command Dashboard & Feedback Loop | B10: =COUNTA(Tracker!$D$82:$D$94) -> 13 | C10: =COUNTIF(Tracker!$J$82:$J$94,"Done") -> 0 | D10: =COUNTIF(Tracker!$J$82:$J$94,"In Progress") -> 0 | E10: =COUNTIF(Tracker!$J$82:$J$94,"Not Started") -> 13 | F10: =COUNTIF(Tracker!$J$82:$J$94,"Blocked") -> 0 | G10: =IF(B10=0,0,C10/B10) -> 0 | H10: =MIN(Tracker!$G$82:$G$94) -> 46322 | I10: =MAX(Tracker!$H$82:$H$94) -> 46525 | J10: =NETWORKDAYS(H10,I10,Holidays!$A$2:$A$40) -> 143
A11: H – Platform, Security & MLOps | B11: =COUNTA(Tracker!$D$95:$D$105) -> 11 | C11: =COUNTIF(Tracker!$J$95:$J$105,"Done") -> 0 | D11: =COUNTIF(Tracker!$J$95:$J$105,"In Progress") -> 0 | E11: =COUNTIF(Tracker!$J$95:$J$105,"Not Started") -> 11 | F11: =COUNTIF(Tracker!$J$95:$J$105,"Blocked") -> 0 | G11: =IF(B11=0,0,C11/B11) -> 0 | H11: =MIN(Tracker!$G$95:$G$105) -> 46311 | I11: =MAX(Tracker!$H$95:$H$105) -> 46554 | J11: =NETWORKDAYS(H11,I11,Holidays!$A$2:$A$40) -> 170
A12: I – Pilot, Validation & Rollout | B12: =COUNTA(Tracker!$D$106:$D$119) -> 14 | C12: =COUNTIF(Tracker!$J$106:$J$119,"Done") -> 0 | D12: =COUNTIF(Tracker!$J$106:$J$119,"In Progress") -> 0 | E12: =COUNTIF(Tracker!$J$106:$J$119,"Not Started") -> 14 | F12: =COUNTIF(Tracker!$J$106:$J$119,"Blocked") -> 0 | G12: =IF(B12=0,0,C12/B12) -> 0 | H12: =MIN(Tracker!$G$106:$G$119) -> 46527 | I12: =MAX(Tracker!$H$106:$H$119) -> 46723 | J12: =NETWORKDAYS(H12,I12,Holidays!$A$2:$A$40) -> 141
A13: Total | B13: =SUM(B4:B12) -> 116 | C13: =SUM(C4:C12) -> 1 | D13: =SUM(D4:D12) -> 0 | E13: =SUM(E4:E12) -> 115 | F13: =SUM(F4:F12) -> 0 | G13: =IF(B13=0,0,C13/B13) -> 0.0086206897 | H13: =MIN(H4:H12) -> 46286 | I13: =MAX(I4:I12) -> 46723 | J13: =NETWORKDAYS(H13,I13,Holidays!$A$2:$A$40) -> 310
A15: Key milestones
A16: Milestone | B16: Tracker row | C16: Target date
A17: NDMA sign-off on proposal | B17: =ROW(Tracker!H5) -> 5 | C17: =Tracker!H5 -> 46310
A18: Pilot district selected | B18: =ROW(Tracker!H6) -> 6 | C18: =Tracker!H6 -> 46318
A19: Core agency feeds live (IMD, CWC) | B19: =ROW(Tracker!H25) -> 25 | C19: =Tracker!H25 -> 46359
A20: Flood forecast backtest passed | B20: =ROW(Tracker!H48) -> 48 | C20: =Tracker!H48 -> 46479
A21: Digital twin animates forecast | B21: =ROW(Tracker!H55) -> 55 | C21: =Tracker!H55 -> 46489
A22: Unified SEOC command screen | B22: =ROW(Tracker!H81) -> 81 | C22: =Tracker!H81 -> 46526
A23: End-to-end integration test | B23: =ROW(Tracker!H106) -> 106 | C23: =Tracker!H106 -> 46540
A24: UAT sign-off | B24: =ROW(Tracker!H108) -> 108 | C24: =Tracker!H108 -> 46568
A25: Shadow mode complete (monsoon 2027) | B25: =ROW(Tracker!H111) -> 111 | C25: =Tracker!H111 -> 46660
A26: Go / no-go for live use | B26: =ROW(Tracker!H112) -> 112 | C26: =Tracker!H112 -> 46667
A27: Phase 3 rollout plan approved | B27: =ROW(Tracker!H119) -> 119 | C27: =Tracker!H119 -> 46723

Sheet Decisions & Dependencies
A1: External Decisions & Dependencies
A2: Everything the team needs from NDMA or another agency. 'Needed by' = start of the first task that waits on it (linked to the Tracker).
A3: # | B3: Decision / dependency | C3: Owner | D3: Blocks | E3: Needed by | F3: Status | G3: Notes
A4: 1 | B4: Proposal walkthrough and sign-off | C4: NDMA | D4: Proposal walkthrough and sign-off with NDMA (P1) | E4: =Tracker!G5 -> 46307 | F4: Open
A5: 2 | B5: Nomination of candidate pilot districts | C5: NDMA / State SDMA | D5: Select Phase 1 pilot district (P2) | E5: =Tracker!G6 -> 46311 | F5: Open | G5: Prefer a well-mapped, flood-prone district (terrain-resolution risk).
A6: 3 | B6: Hosting / cloud approval (data residency in India) | C6: NDMA IT | D6: Hosting decision (MeghRaj / NIC / GovCloud) (H0) | E6: =Tracker!G95 -> 46311 | F6: Open | G6: Blocks all environments.
A7: 4 | B7: IMD data-sharing agreement | C7: IMD | D7: IMD data-sharing agreement (D1) | E7: =Tracker!G10 -> 46321 | F7: Open | G7: Formal agreements from day one (inter-agency risk).
A8: 5 | B8: CWC data-sharing agreement | C8: CWC | D8: CWC data-sharing agreement (D2) | E8: =Tracker!G11 -> 46321 | F8: Open
A9: 6 | B9: ISRO / NRSC imagery access | C9: NRSC | D9: ISRO / NRSC satellite data access (D3) | E9: =Tracker!G12 -> 46321 | F9: Open
A10: 7 | B10: Survey of India DEM licence | C10: Survey of India | D10: Survey of India high-resolution DEM licence (D4) | E10: =Tracker!G13 -> 46321 | F10: Open
A11: 8 | B11: Google Maps Platform budget | C11: NDMA Finance | D11: Google Maps Platform licence and billing (D6) | E11: =Tracker!G15 -> 46311 | F11: Open
A12: 9 | B12: Commercial imagery procurement | C12: NDMA Procurement | D12: Commercial high-resolution imagery procurement (D7) | E12: =Tracker!G16 -> 46321 | F12: Open | G12: Phase 1 pilot district only.
A13: 10 | B13: Privacy policy legal review (DPDP Act 2023) | C13: NDMA Legal | D13: Data governance and privacy policy (G1) | E13: =Tracker!G17 -> 46311 | F13: Open
A14: 11 | B14: IDRN inventory access | C14: NDMA / NIDM | D14: IDRN resource inventory import (I13) | E14: =Tracker!G32 -> 46346 | F14: Open
A15: 12 | B15: Pilot sensor feed access | C15: State water resources dept / vendor | D15: River / rain gauge sensor telemetry (pilot) (I14) | E15: =Tracker!G33 -> 46350 | F15: Open
A16: 13 | B16: WhatsApp Business API account | C16: NDMA | D16: WhatsApp ground-reporting bot (I17) | E16: =Tracker!G34 -> 46350 | F16: Open
A17: 14 | B17: NDRF / SDRF unit data and tracking feed | C17: NDRF / SDRF | D17: NDRF / SDRF unit and capability registry (F1); GPS / radio tracking integration (F2) | E17: =Tracker!G74 -> 46353 | F17: Open
A18: 15 | B18: SACHET / Cell Broadcast export format | C18: NDMA / C-DOT | D18: Export route and shelter plans for official channels (E14) | E18: =Tracker!G73 -> 46507 | F18: Open | G18: Operators issue messages; system never auto-sends.
A19: 16 | B19: Security auditor engagement | C19: NDMA IT | D19: Security audit (CERT-In empanelled auditor) (H4) | E19: =Tracker!G101 -> 46541 | F19: Open | G19: CERT-In empanelled.

Sheet Risks
A1: Risk Register
A2: Risks 1–5 from proposal section 7; 6–8 added for delivery. Impact / Likelihood are initial team estimates — review with NDMA.
A3: # | B3: Risk | C3: Impact | D3: Likelihood | E3: Mitigation | F3: Linked tasks | G3: Status
A4: 1 | B4: Terrain data resolution — inconsistent elevation data distorts hazard-flow predictions. | C4: High | D4: Medium | E4: Launch Phase 1 in a single well-mapped pilot district before scaling. | F4: P2, D4, I9 | G4: Open
A5: 2 | B5: Crowdsourced data reliability — misinformation or false reports corrupt the model. | C5: High | D5: High | E5: Strict NLP/verification filtering and trust scores before ingestion; operator review queue. | F5: I20, FB3, X5 | G5: Open
A6: 3 | B6: Model trust & validation — wrong predictions misdirect forces or plans. | C6: High | D6: Medium | E6: Backtest against historical data and run in shadow mode before live decisions. | F6: M11, T9, T10, V4, V5 | G6: Open
A7: 4 | B7: Data privacy & consent — citizen location and social data create legal liability. | C7: High | D7: Medium | E7: Data-governance and privacy policy built alongside the technical build; consent on every report. | F7: G1, G2, G3 | G7: Open
A8: 5 | B8: Inter-agency coordination — IMD, CWC, ISRO use siloed, incompatible formats. | C8: High | D8: High | E8: Formal data-sharing agreements and a common schema from day one. | F8: D1, D2, D3, I1 | G8: Open
A9: 6 | B9: Agreement delays push the schedule (agency approvals are outside team control). | C9: High | D9: High | E9: Start agreements immediately after pilot selection; build on open data (Copernicus, OSM) meanwhile. | F9: D1–D7, I8 | G9: Open
A10: 7 | B10: Shadow-mode window depends on monsoon timing; a quiet season gives few events. | C10: Medium | D10: Medium | E10: Supplement with historical replays; extend shadow mode or add a second pilot basin if needed. | F10: V4, T9 | G10: Open
A11: 8 | B11: System unavailable during a live disaster (surge load, outages). | C11: High | D11: Low | E11: Load testing at 3× peak, DR drill and low-bandwidth mode. | F11: H9, H10, U10 | G11: Open

Sheet Holidays
A1: Date | B1: Holiday | D1: Edit this list to match the NDMA gazetted holiday calendar; Working days on every tab uses A2:A40. The planned dates on the Tracker were scheduled with this list.
A2: 46315 | B2: Dussehra
A3: 46381 | B3: Christmas
A4: 46413 | B4: Republic Day
A5: 46472 | B5: Good Friday
